Workbook

Sheet Source
A1: OrderNbr | B1: Customer | C1: CustomerName | D1: Date | E1: OrderTotal | F1: CreatedBy
A2: SO00000687 | B2: 1250000116 | C2: CITY GOVERNMENT OF DAVAO | D2: 45250 | E2: ₱4372.25 | F2: GRACE POLPOL
A3: SO00000012 | B3: 1250000505 | C3: STAR PAPER CORPORATION | D3: 45294 | E3: ₱1362.00 | F3: ANGELI SUMINGIT
A4: SO00000005 | B4: 1250001764 | C4: STENIEL MINDANAO PACKAGING CORPORATION | D4: 45294 | E4: ₱1500.00 | F4: ANGELI SUMINGIT
A5: SO00000028 | B5: 1250001496 | C5: COMFAC CORPORATION | D5: 45294 | E5: ₱1916.00 | F5: ANGELI SUMINGIT
A6: SO00000021 | B6: 1200006565 | C6: NXTGEN TECHNOLOGIES INC | D6: 45294 | E6: ₱2148.80 | F6: ANGELI SUMINGIT
A7: SO00000026 | B7: 1250004966 | C7: INFIMAX HEALTH PRODUCTS | D7: 45294 | E7: ₱2365.80 | F7: ANGELI SUMINGIT
A8: SO00000020 | B8: 1250001764 | C8: STENIEL MINDANAO PACKAGING CORPORATION | D8: 45294 | E8: ₱2367.50 | F8: ANGELI SUMINGIT
A9: SO00000013 | B9: 1250001142 | C9: DEPT. OF HUMAN SETTLEMENTS & URBAN DEV'T | D9: 45294 | E9: ₱38256.00 | F9: GRACE POLPOL
A10: SO00000097 | B10: 1200006417 | C10: PHIL.FIBER INDUSTRY DEV'T AUTHORITY | D10: 45295 | E10: ₱1500.00 | F10: GRACE POLPOL
A11: SO00000071 | B11: 1250010315 | C11: HI5 SOLUTIONS OPC | D11: 45295 | E11: ₱1600.00 | F11: ANGELI SUMINGIT
A12: SO00000096 | B12: 1250004938 | C12: B.P.I. - BAJADA (FRONTING CONPINCO) | D12: 45295 | E12: ₱4762.10 | F12: ANGELI SUMINGIT
A13: SO00000070 | B13: 1250003997 | C13: INSULAR OIL CORPORATION | D13: 45295 | E13: ₱5265.00 | F13: ANGELI SUMINGIT
... A201: SO00001324 | B201: 1250001273 | C201: MILLENNIUM SPECIALTY COCO PRODUCTSINC. | D201: 45337 | E201: ₱1200.00 | F201: ANGELI SUMINGIT

Sheet Rhea
A1: OrderNbr | B1: Customer | C1: CustomerName | D1: Date | E1: OrderTotal | F1: CreatedBy
A2: SO00000687 | B2: 1250000116 | C2: CITY GOVERNMENT OF DAVAO | D2: 45250 | E2: 4372.25 | F2: GRACE POLPOL
A3: SO00000012 | B3: 1250000505 | C3: STAR PAPER CORPORATION | D3: 45294 | E3: 1362 | F3: ANGELI SUMINGIT
A4: SO00000005 | B4: 1250001764 | C4: STENIEL MINDANAO PACKAGING CORPORATION | D4: 45294 | E4: 1500 | F4: ANGELI SUMINGIT
A5: SO00000028 | B5: 1250001496 | C5: COMFAC CORPORATION | D5: 45294 | E5: 1916 | F5: ANGELI SUMINGIT
A6: SO00000021 | B6: 1200006565 | C6: NXTGEN TECHNOLOGIES INC | D6: 45294 | E6: 2148.8 | F6: ANGELI SUMINGIT
A7: SO00000026 | B7: 1250004966 | C7: INFIMAX HEALTH PRODUCTS | D7: 45294 | E7: 2365.8 | F7: ANGELI SUMINGIT
A8: SO00000020 | B8: 1250001764 | C8: STENIEL MINDANAO PACKAGING CORPORATION | D8: 45294 | E8: 2367.5 | F8: ANGELI SUMINGIT
A9: SO00000013 | B9: 1250001142 | C9: DEPT. OF HUMAN SETTLEMENTS & URBAN DEV'T | D9: 45294 | E9: 38256 | F9: GRACE POLPOL
A10: SO00000097 | B10: 1200006417 | C10: PHIL.FIBER INDUSTRY DEV'T AUTHORITY | D10: 45295 | E10: 1500 | F10: GRACE POLPOL
A11: SO00000071 | B11: 1250010315 | C11: HI5 SOLUTIONS OPC | D11: 45295 | E11: 1600 | F11: ANGELI SUMINGIT
A12: SO00000096 | B12: 1250004938 | C12: B.P.I. - BAJADA (FRONTING CONPINCO) | D12: 45295 | E12: 4762.1 | F12: ANGELI SUMINGIT
A13: SO00000070 | B13: 1250003997 | C13: INSULAR OIL CORPORATION | D13: 45295 | E13: 5265 | F13: ANGELI SUMINGIT
... A201: SO00001324 | B201: 1250001273 | C201: MILLENNIUM SPECIALTY COCO PRODUCTSINC. | D201: 45337 | E201: 1200 | F201: ANGELI SUMINGIT

Sheet rhea_rhea
B122: =SUMIF(Rhea!D2:D1000,A122,Rhea!E:E) -> 0
B123: =SUMIF(Rhea!D3:D1000,A123,Rhea!E:E) -> 0
B124: =SUMIF(Rhea!D4:D1000,A124,Rhea!E:E) -> 0
B125: =SUMIF(Rhea!D5:D1000,A125,Rhea!E:E) -> 0
B126: =SUMIF(Rhea!D6:D1000,A126,Rhea!E:E) -> 0
B127: =SUMIF(Rhea!D7:D1000,A127,Rhea!E:E) -> 0
B128: =SUMIF(Rhea!D8:D1000,A128,Rhea!E:E) -> 0
B129: =SUMIF(Rhea!D9:D1000,A129,Rhea!E:E) -> 0
B130: =SUMIF(Rhea!D10:D1000,A130,Rhea!E:E) -> 0
B131: =SUMIF(Rhea!D11:D1000,A131,Rhea!E:E) -> 0
B132: =SUMIF(Rhea!D12:D1000,A132,Rhea!E:E) -> 0
B133: =SUMIF(Rhea!D13:D1000,A133,Rhea!E:E) -> 0
B134: =SUMIF(Rhea!D14:D1000,A134,Rhea!E:E) -> 0
B135: =SUMIF(Rhea!D15:D1000,A135,Rhea!E:E) -> 0
B136: =SUMIF(Rhea!D16:D1000,A136,Rhea!E:E) -> 0
B137: =SUMIF(Rhea!D17:D1000,A137,Rhea!E:E) -> 0
B138: =SUMIF(Rhea!D18:D1000,A138,Rhea!E:E) -> 0
B139: =SUMIF(Rhea!D19:D1000,A139,Rhea!E:E) -> 0
B140: =SUMIF(Rhea!D20:D1000,A140,Rhea!E:E) -> 0
B141: =SUMIF(Rhea!D21:D1000,A141,Rhea!E:E) -> 0
B142: =SUMIF(Rhea!D22:D1000,A142,Rhea!E:E) -> 0
B143: =SUMIF(Rhea!D23:D1000,A143,Rhea!E:E) -> 0
B144: =SUMIF(Rhea!D24:D1000,A144,Rhea!E:E) -> 0
B145: =SUMIF(Rhea!D25:D1000,A145,Rhea!E:E) -> 0
B146: =SUMIF(Rhea!D26:D1000,A146,Rhea!E:E) -> 0
B147: =SUMIF(Rhea!D27:D1000,A147,Rhea!E:E) -> 0
B148: =SUMIF(Rhea!D28:D1000,A148,Rhea!E:E) -> 0
B149: =SUMIF(Rhea!D29:D1000,A149,Rhea!E:E) -> 0
B150: =SUMIF(Rhea!D30:D1000,A150,Rhea!E:E) -> 0
B151: =SUMIF(Rhea!D31:D1000,A151,Rhea!E:E) -> 0
B152: =SUMIF(Rhea!D32:D1000,A152,Rhea!E:E) -> 0
B153: =SUMIF(Rhea!D33:D1000,A153,Rhea!E:E) -> 0
B154: =SUMIF(Rhea!D34:D1000,A154,Rhea!E:E) -> 0
B155: =SUMIF(Rhea!D35:D1000,A155,Rhea!E:E) -> 0
B156: =SUMIF(Rhea!D36:D1000,A156,Rhea!E:E) -> 0
B157: =SUMIF(Rhea!D37:D1000,A157,Rhea!E:E) -> 0

Sheet John 1
B23: amounting to | C23: 0.54977723 | D23: total | E23: 1455920.9 | G23: avaergae number pf transaction per month | H23: 1.4936709 | I23: jan
C24: =C23*100 -> 54.977723 | D24: ot the sales | H24: 1.7608696 | I24: feb

Sheet Copy of John 1
A1: OrderNbr | B1: Customer | C1: CustomerName | D1: Date | E1: OrderTotal | F1: CreatedBy | K1: CustomerName | L1: month | M1: OrderTotal | R1: =IFERROR(__xludf.DUMMYFUNCTION("QUERY('Copy of John 1'!C:E, ""SELECT C, SUM(E) WHERE C IS NOT NULL GROUP BY C ORDER BY SUM(E) DESC LIMIT 5"", 1)"),"CustomerName") -> CustomerName | S1: =IFERROR(__xludf.DUMMYFUNCTION("""COMPUTED_VALUE"""),"sum OrderTotal") -> sum OrderTotal | U1: CustomerName | V1: count OrderTotal | AT1: =IFERROR(__xludf.DUMMYFUNCTION("QUERY(AH2:AJ239, ""SELECT AH, AJ WHERE AI > 0 ORDER BY AH DESC"", 1)"),"AFP & POLICE SAVINGS LOAN ASSN (AFPSLAI)") -> AFP & POLICE SAVINGS LOAN ASSN (AFPSLAI) | AU1: =IFERROR(__xludf.DUMMYFUNCTION("""COMPUTED_VALUE"""),"1") -> 1
A2: SO00000687 | B2: 1250000116.00 | C2: CITY GOVERNMENT OF DAVAO | D2: 45250 | E2: 4372.25 | F2: GRACE POLPOL | K2: CITY GOVERNMENT OF DAVAO | L2: {=text(D2:D201,"mmmm")} -> November | M2: 4372.25 | R2: =IFERROR(__xludf.DUMMYFUNCTION("""COMPUTED_VALUE"""),"MUNICIPALITY OF LUPON - LGU") -> MUNICIPALITY OF LUPON - LGU | S2: =IFERROR(__xludf.DUMMYFUNCTION("""COMPUTED_VALUE"""),636382.0) -> 636382 | U2: MUNICIPALITY OF LUPON - LGU | V2: 21 | AL2: =IFERROR(__xludf.DUMMYFUNCTION("QUERY(AH1:AJ1000)"),"CustomerName") -> CustomerName | AM2: =IFERROR(__xludf.DUMMYFUNCTION("""COMPUTED_VALUE"""),"month") -> month | AN2: =IFERROR(__xludf.DUMMYFUNCTION("""COMPUTED_VALUE"""),"COUNTA of month") -> COUNTA of month | AP2: =IFERROR(__xludf.DUMMYFUNCTION("QUERY(AH1:AJ239)"),"CustomerName") -> CustomerName | AQ2: =IFERROR(__xludf.DUMMYFUNCTION("""COMPUTED_VALUE"""),"month") -> month | AR2: =IFERROR(__xludf.DUMMYFUNCTION("""COMPUTED_VALUE"""),"COUNTA of month") -> COUNTA of month
A3: SO00000012 | B3: 1250000505.00 | C3: STAR PAPER CORPORATION | D3: 45294 | E3: 1362 | F3: ANGELI SUMINGIT | K3: STAR PAPER CORPORATION | L3: January | M3: 1362 | R3: =IFERROR(__xludf.DUMMYFUNCTION("""COMPUTED_VALUE"""),"AMERICARES FOUNDATION INC.") -> AMERICARES FOUNDATION INC. | S3: =IFERROR(__xludf.DUMMYFUNCTION("""COMPUTED_VALUE"""),365925.0) -> 365925 | U3: STENIEL MINDANAO PACKAGING CORPORATION | V3: 14 | AL3: =IFERROR(__xludf.DUMMYFUNCTION("""COMPUTED_VALUE"""),"AFP & POLICE SAVINGS LOAN ASSN (AFPSLAI)") -> AFP & POLICE SAVINGS LOAN ASSN (AFPSLAI) | AM3: =IFERROR(__xludf.DUMMYFUNCTION("""COMPUTED_VALUE"""),"February") -> February | AN3: =IFERROR(__xludf.DUMMYFUNCTION("""COMPUTED_VALUE"""),1.0) -> 1 | AP3: =IFERROR(__xludf.DUMMYFUNCTION("""COMPUTED_VALUE"""),"AFP & POLICE SAVINGS LOAN ASSN (AFPSLAI)") -> AFP & POLICE SAVINGS LOAN ASSN (AFPSLAI) | AQ3: =IFERROR(__xludf.DUMMYFUNCTION("""COMPUTED_VALUE"""),"February") -> February | AR3: =IFERROR(__xludf.DUMMYFUNCTION("""COMPUTED_VALUE"""),1.0) -> 1 | AT3: =IFERROR(__xludf.DUMMYFUNCTION("QUERY('Copy of John 1'!K1:M201, ""SELECT K, COUNT(M) WHERE K IS NOT NULL GROUP BY K ORDER BY COUNT(M) DESC LIMIT 5"", 1)"),"CustomerName") -> CustomerName | AU3: =IFERROR(__xludf.DUMMYFUNCTION("""COMPUTED_VALUE"""),"count OrderTotal") -> count OrderTotal
A4: SO00000005 | B4: 1250001764.00 | C4: STENIEL MINDANAO PACKAGING CORPORATION | D4: 45294 | E4: 1500 | F4: ANGELI SUMINGIT | K4: STENIEL MINDANAO PACKAGING CORPORATION | L4: January | M4: 1500 | R4: =IFERROR(__xludf.DUMMYFUNCTION("""COMPUTED_VALUE"""),"STENIEL MINDANAO PACKAGING CORPORATION") -> STENIEL MINDANAO PACKAGING CORPORATION | S4: =IFERROR(__xludf.DUMMYFUNCTION("""COMPUTED_VALUE"""),248363.5) -> 248363.5 | U4: CIVIL SERVICE COMMISSION-REG. XI | V4: 6 | AL4: =IFERROR(__xludf.DUMMYFUNCTION("""COMPUTED_VALUE"""),"AFP & POLICE SAVINGS LOAN ASSN (AFPSLAI) Total") -> AFP & POLICE SAVINGS LOAN ASSN (AFPSLAI) Total | AN4: =IFERROR(__xludf.DUMMYFUNCTION("""COMPUTED_VALUE"""),1.0) -> 1 | AP4: =IFERROR(__xludf.DUMMYFUNCTION("""COMPUTED_VALUE"""),"AFP & POLICE SAVINGS LOAN ASSN (AFPSLAI) Total") -> AFP & POLICE SAVINGS LOAN ASSN (AFPSLAI) Total | AR4: =IFERROR(__xludf.DUMMYFUNCTION("""COMPUTED_VALUE"""),1.0) -> 1 | AT4: =IFERROR(__xludf.DUMMYFUNCTION("""COMPUTED_VALUE"""),"MUNICIPALITY OF LUPON - LGU") -> MUNICIPALITY OF LUPON - LGU | AU4: =IFERROR(__xludf.DUMMYFUNCTION("""COMPUTED_VALUE"""),21.0) -> 21
A5: SO00000028 | B5: 1250001496.00 | C5: COMFAC CORPORATION | D5: 45294 | E5: 4372.25 | F5: ANGELI SUMINGIT | K5: COMFAC CORPORATION | L5: January | M5: 4372.25 | R5: =IFERROR(__xludf.DUMMYFUNCTION("""COMPUTED_VALUE"""),"DEPT. OF HUMAN SETTLEMENTS & URBAN DEV'T") -> DEPT. OF HUMAN SETTLEMENTS & URBAN DEV'T | S5: =IFERROR(__xludf.DUMMYFUNCTION("""COMPUTED_VALUE"""),146676.0) -> 146676 | U5: EC GONZAGA ENTERPRISES | V5: 6 | AL5: =IFERROR(__xludf.DUMMYFUNCTION("""COMPUTED_VALUE"""),"AGRI DAVAO INCORPORATED") -> AGRI DAVAO INCORPORATED | AM5: =IFERROR(__xludf.DUMMYFUNCTION("""COMPUTED_VALUE"""),"February") -> February | AN5: =IFERROR(__xludf.DUMMYFUNCTION("""COMPUTED_VALUE"""),1.0) -> 1 | AP5: =IFERROR(__xludf.DUMMYFUNCTION("""COMPUTED_VALUE"""),"AGRI DAVAO INCORPORATED") -> AGRI DAVAO INCORPORATED | AQ5: =IFERROR(__xludf.DUMMYFUNCTION("""COMPUTED_VALUE"""),"February") -> February | AR5: =IFERROR(__xludf.DUMMYFUNCTION("""COMPUTED_VALUE"""),1.0) -> 1 | AT5: =IFERROR(__xludf.DUMMYFUNCTION("""COMPUTED_VALUE"""),"STENIEL MINDANAO PACKAGING CORPORATION") -> STENIEL MINDANAO PACKAGING CORPORATION | AU5: =IFERROR(__xludf.DUMMYFUNCTION("""COMPUTED_VALUE"""),14.0) -> 14
A6: SO00000021 | B6: 1200006565.00 | C6: NXTGEN TECHNOLOGIES INC | D6: 45294 | E6: 2148.8 | F6: ANGELI SUMINGIT | K6: NXTGEN TECHNOLOGIES INC | L6: January | M6: 2148.8 | R6: =IFERROR(__xludf.DUMMYFUNCTION("""COMPUTED_VALUE"""),"EC GONZAGA ENTERPRISES") -> EC GONZAGA ENTERPRISES | S6: =IFERROR(__xludf.DUMMYFUNCTION("""COMPUTED_VALUE"""),58574.45) -> 58574.45 | U6: ANTONIO'S GRILL | V6: 5 | AM6: =IFERROR(__xludf.DUMMYFUNCTION("""COMPUTED_VALUE"""),"January") -> January | AN6: =IFERROR(__xludf.DUMMYFUNCTION("""COMPUTED_VALUE"""),1.0) -> 1 | AQ6: =IFERROR(__xludf.DUMMYFUNCTION("""COMPUTED_VALUE"""),"January") -> January | AR6: =IFERROR(__xludf.DUMMYFUNCTION("""COMPUTED_VALUE"""),1.0) -> 1 | AT6: =IFERROR(__xludf.DUMMYFUNCTION("""COMPUTED_VALUE"""),"CIVIL SERVICE COMMISSION-REG. XI") -> CIVIL SERVICE COMMISSION-REG. XI | AU6: =IFERROR(__xludf.DUMMYFUNCTION("""COMPUTED_VALUE"""),6.0) -> 6
A7: SO00000026 | B7: 1250004966.00 | C7: INFIMAX HEALTH PRODUCTS | D7: 45294 | E7: 2365.8 | F7: ANGELI SUMINGIT | K7: INFIMAX HEALTH PRODUCTS | L7: January | M7: 2365.8 | AL7: =IFERROR(__xludf.DUMMYFUNCTION("""COMPUTED_VALUE"""),"AGRI DAVAO INCORPORATED Total") -> AGRI DAVAO INCORPORATED Total | AN7: =IFERROR(__xludf.DUMMYFUNCTION("""COMPUTED_VALUE"""),2.0) -> 2 | AP7: =IFERROR(__xludf.DUMMYFUNCTION("""COMPUTED_VALUE"""),"AGRI DAVAO INCORPORATED Total") -> AGRI DAVAO INCORPORATED Total | AR7: =IFERROR(__xludf.DUMMYFUNCTION("""COMPUTED_VALUE"""),2.0) -> 2 | AT7: =IFERROR(__xludf.DUMMYFUNCTION("""COMPUTED_VALUE"""),"EC GONZAGA ENTERPRISES") -> EC GONZAGA ENTERPRISES | AU7: =IFERROR(__xludf.DUMMYFUNCTION("""COMPUTED_VALUE"""),6.0) -> 6
A8: SO00000020 | B8: 1250001764.00 | C8: STENIEL MINDANAO PACKAGING CORPORATION | D8: 45294 | E8: 2367.5 | F8: ANGELI SUMINGIT | K8: STENIEL MINDANAO PACKAGING CORPORATION | L8: January | M8: 2367.5 | T8: =sum(S2:S6) -> 1455920.9 | AL8: =IFERROR(__xludf.DUMMYFUNCTION("""COMPUTED_VALUE"""),"AKTIV MULTI TRADING CO. PHILS. INC.") -> AKTIV MULTI TRADING CO. PHILS. INC. | AM8: =IFERROR(__xludf.DUMMYFUNCTION("""COMPUTED_VALUE"""),"January") -> January | AN8: =IFERROR(__xludf.DUMMYFUNCTION("""COMPUTED_VALUE"""),1.0) -> 1 | AP8: =IFERROR(__xludf.DUMMYFUNCTION("""COMPUTED_VALUE"""),"AKTIV MULTI TRADING CO. PHILS. INC.") -> AKTIV MULTI TRADING CO. PHILS. INC. | AQ8: =IFERROR(__xludf.DUMMYFUNCTION("""COMPUTED_VALUE"""),"January") -> January | AR8: =IFERROR(__xludf.DUMMYFUNCTION("""COMPUTED_VALUE"""),1.0) -> 1 | AT8: =IFERROR(__xludf.DUMMYFUNCTION("""COMPUTED_VALUE"""),"ANTONIO'S GRILL") -> ANTONIO'S GRILL | AU8: =IFERROR(__xludf.DUMMYFUNCTION("""COMPUTED_VALUE"""),5.0) -> 5
A9: SO00000013 | B9: 1250001142.00 | C9: DEPT. OF HUMAN SETTLEMENTS & URBAN DEV'T | D9: 45294 | E9: 38256 | F9: GRACE POLPOL | K9: DEPT. OF HUMAN SETTLEMENTS & URBAN DEV'T | L9: January | M9: 38256 | AL9: =IFERROR(__xludf.DUMMYFUNCTION("""COMPUTED_VALUE"""),"AKTIV MULTI TRADING CO. PHILS. INC. Total") -> AKTIV MULTI TRADING CO. PHILS. INC. Total | AN9: =IFERROR(__xludf.DUMMYFUNCTION("""COMPUTED_VALUE"""),1.0) -> 1 | AP9: =IFERROR(__xludf.DUMMYFUNCTION("""COMPUTED_VALUE"""),"AKTIV MULTI TRADING CO. PHILS. INC. Total") -> AKTIV MULTI TRADING CO. PHILS. INC. Total | AR9: =IFERROR(__xludf.DUMMYFUNCTION("""COMPUTED_VALUE"""),1.0) -> 1
A10: SO00000097 | B10: 1200006417.00 | C10: PHIL.FIBER INDUSTRY DEV'T AUTHORITY | D10: 45295 | E10: 1500 | F10: GRACE POLPOL | K10: PHIL.FIBER INDUSTRY DEV'T AUTHORITY | L10: January | M10: 1500 | AL10: =IFERROR(__xludf.DUMMYFUNCTION("""COMPUTED_VALUE"""),"AMALGATED CAPITAL INCORPORATED") -> AMALGATED CAPITAL INCORPORATED | AM10: =IFERROR(__xludf.DUMMYFUNCTION("""COMPUTED_VALUE"""),"February") -> February | AN10: =IFERROR(__xludf.DUMMYFUNCTION("""COMPUTED_VALUE"""),3.0) -> 3 | AP10: =IFERROR(__xludf.DUMMYFUNCTION("""COMPUTED_VALUE"""),"AMALGATED CAPITAL INCORPORATED") -> AMALGATED CAPITAL INCORPORATED | AQ10: =IFERROR(__xludf.DUMMYFUNCTION("""COMPUTED_VALUE"""),"February") -> February | AR10: =IFERROR(__xludf.DUMMYFUNCTION("""COMPUTED_VALUE"""),3.0) -> 3 | AT10: =IFERROR(__xludf.DUMMYFUNCTION("QUERY('Copy of John 1'!K1:M201, ""SELECT K, COUNT(M) WHERE K IS NOT NULL AND L = 'January' GROUP BY K ORDER BY COUNT(M) DESC LIMIT 5"", 1)"),"CustomerName") -> CustomerName | AU10: =IFERROR(__xludf.DUMMYFUNCTION("""COMPUTED_VALUE"""),"count OrderTotal") -> count OrderTotal
A11: SO00000071 | B11: 1250010315.00 | C11: HI5 SOLUTIONS OPC | D11: 45295 | E11: 1600 | F11: ANGELI SUMINGIT | K11: HI5 SOLUTIONS OPC | L11: January | M11: 1600 | AL11: =IFERROR(__xludf.DUMMYFUNCTION("""COMPUTED_VALUE"""),"AMALGATED CAPITAL INCORPORATED Total") -> AMALGATED CAPITAL INCORPORATED Total | AN11: =IFERROR(__xludf.DUMMYFUNCTION("""COMPUTED_VALUE"""),3.0) -> 3 | AP11: =IFERROR(__xludf.DUMMYFUNCTION("""COMPUTED_VALUE"""),"AMALGATED CAPITAL INCORPORATED Total") -> AMALGATED CAPITAL INCORPORATED Total | AR11: =IFERROR(__xludf.DUMMYFUNCTION("""COMPUTED_VALUE"""),3.0) -> 3 | AT11: =IFERROR(__xludf.DUMMYFUNCTION("""COMPUTED_VALUE"""),"STENIEL MINDANAO PACKAGING CORPORATION") -> STENIEL MINDANAO PACKAGING CORPORATION | AU11: =IFERROR(__xludf.DUMMYFUNCTION("""COMPUTED_VALUE"""),9.0) -> 9
A12: SO00000096 | B12: 1250004938.00 | C12: B.P.I. - BAJADA (FRONTING CONPINCO) | D12: 45295 | E12: 4762.1 | F12: ANGELI SUMINGIT | K12: B.P.I. - BAJADA (FRONTING CONPINCO) | L12: January | M12: 4762.1 | AL12: =IFERROR(__xludf.DUMMYFUNCTION("""COMPUTED_VALUE"""),"AMERICARES FOUNDATION INC.") -> AMERICARES FOUNDATION INC. | AM12: =IFERROR(__xludf.DUMMYFUNCTION("""COMPUTED_VALUE"""),"January") -> January | AN12: =IFERROR(__xludf.DUMMYFUNCTION("""COMPUTED_VALUE"""),1.0) -> 1 | AP12: =IFERROR(__xludf.DUMMYFUNCTION("""COMPUTED_VALUE"""),"AMERICARES FOUNDATION INC.") -> AMERICARES FOUNDATION INC. | AQ12: =IFERROR(__xludf.DUMMYFUNCTION("""COMPUTED_VALUE"""),"January") -> January | AR12: =IFERROR(__xludf.DUMMYFUNCTION("""COMPUTED_VALUE"""),1.0) -> 1 | AT12: =IFERROR(__xludf.DUMMYFUNCTION("""COMPUTED_VALUE"""),"ANTONIO'S GRILL") -> ANTONIO'S GRILL | AU12: =IFERROR(__xludf.DUMMYFUNCTION("""COMPUTED_VALUE"""),5.0) -> 5
A13: SO00000070 | B13: 1250003997.00 | C13: INSULAR OIL CORPORATION | D13: 45295 | E13: 5265 | F13: ANGELI SUMINGIT | K13: INSULAR OIL CORPORATION | L13: January | M13: 5265 | AL13: =IFERROR(__xludf.DUMMYFUNCTION("""COMPUTED_VALUE"""),"AMERICARES FOUNDATION INC. Total") -> AMERICARES FOUNDATION INC. Total | AN13: =IFERROR(__xludf.DUMMYFUNCTION("""COMPUTED_VALUE"""),1.0) -> 1 | AP13: =IFERROR(__xludf.DUMMYFUNCTION("""COMPUTED_VALUE"""),"AMERICARES FOUNDATION INC. Total") -> AMERICARES FOUNDATION INC. Total | AR13: =IFERROR(__xludf.DUMMYFUNCTION("""COMPUTED_VALUE"""),1.0) -> 1 | AT13: =IFERROR(__xludf.DUMMYFUNCTION("""COMPUTED_VALUE"""),"CIVIL SERVICE COMMISSION-REG. XI") -> CIVIL SERVICE COMMISSION-REG. XI | AU13: =IFERROR(__xludf.DUMMYFUNCTION("""COMPUTED_VALUE"""),5.0) -> 5
A14: SO00000103 | B14: 1250003421.00 | C14: LAND BANK OF THE PHILS. - NABUNTURAN | D14: 45295 | E14: 51900 | F14: GRACE POLPOL | K14: LAND BANK OF THE PHILS. - NABUNTURAN | L14: January | M14: 51900 | AL14: =IFERROR(__xludf.DUMMYFUNCTION("""COMPUTED_VALUE"""),"AMESCO DRUG CORPORATION") -> AMESCO DRUG CORPORATION | AM14: =IFERROR(__xludf.DUMMYFUNCTION("""COMPUTED_VALUE"""),"February") -> February | AN14: =IFERROR(__xludf.DUMMYFUNCTION("""COMPUTED_VALUE"""),1.0) -> 1 | AP14: =IFERROR(__xludf.DUMMYFUNCTION("""COMPUTED_VALUE"""),"AMESCO DRUG CORPORATION") -> AMESCO DRUG CORPORATION | AQ14: =IFERROR(__xludf.DUMMYFUNCTION("""COMPUTED_VALUE"""),"February") -> February | AR14: =IFERROR(__xludf.DUMMYFUNCTION("""COMPUTED_VALUE"""),1.0) -> 1 | AT14: =IFERROR(__xludf.DUMMYFUNCTION("""COMPUTED_VALUE"""),"COMFAC CORPORATION") -> COMFAC CORPORATION | AU14: =IFERROR(__xludf.DUMMYFUNCTION("""COMPUTED_VALUE"""),4.0) -> 4
A15: SO00000146 | B15: 1200009067.00 | C15: IVN ENTERPRISES | D15: 45296 | E15: 2060 | F15: ANGELI SUMINGIT | K15: IVN ENTERPRISES | L15: January | M15: 2060 | AL15: =IFERROR(__xludf.DUMMYFUNCTION("""COMPUTED_VALUE"""),"AMESCO DRUG CORPORATION Total") -> AMESCO DRUG CORPORATION Total | AN15: =IFERROR(__xludf.DUMMYFUNCTION("""COMPUTED_VALUE"""),1.0) -> 1 | AP15: =IFERROR(__xludf.DUMMYFUNCTION("""COMPUTED_VALUE"""),"AMESCO DRUG CORPORATION Total") -> AMESCO DRUG CORPORATION Total | AR15: =IFERROR(__xludf.DUMMYFUNCTION("""COMPUTED_VALUE"""),1.0) -> 1 | AT15: =IFERROR(__xludf.DUMMYFUNCTION("""COMPUTED_VALUE"""),"DEPT. OF HUMAN SETTLEMENTS & URBAN DEV'T") -> DEPT. OF HUMAN SETTLEMENTS & URBAN DEV'T | AU15: =IFERROR(__xludf.DUMMYFUNCTION("""COMPUTED_VALUE"""),4.0) -> 4
A16: SO00000117 | B16: 1250000118.00 | C16: KIM GUAN TRADING CO. INC. | D16: 45296 | E16: 4097.5 | F16: ANGELI SUMINGIT | K16: KIM GUAN TRADING CO. INC. | L16: January | M16: 4097.5 | AL16: =IFERROR(__xludf.DUMMYFUNCTION("""COMPUTED_VALUE"""),"ANTONIO'S GRILL") -> ANTONIO'S GRILL | AM16: =IFERROR(__xludf.DUMMYFUNCTION("""COMPUTED_VALUE"""),"January") -> January | AN16: =IFERROR(__xludf.DUMMYFUNCTION("""COMPUTED_VALUE"""),5.0) -> 5 | AP16: =IFERROR(__xludf.DUMMYFUNCTION("""COMPUTED_VALUE"""),"ANTONIO'S GRILL") -> ANTONIO'S GRILL | AQ16: =IFERROR(__xludf.DUMMYFUNCTION("""COMPUTED_VALUE"""),"January") -> January | AR16: =IFERROR(__xludf.DUMMYFUNCTION("""COMPUTED_VALUE"""),5.0) -> 5
A17: SO00000124 | B17: 1250001741.00 | C17: SPAMAST | D17: 45296 | E17: 6230 | F17: GRACE POLPOL | K17: SPAMAST | L17: January | M17: 6230 | AL17: =IFERROR(__xludf.DUMMYFUNCTION("""COMPUTED_VALUE"""),"ANTONIO'S GRILL Total") -> ANTONIO'S GRILL Total | AN17: =IFERROR(__xludf.DUMMYFUNCTION("""COMPUTED_VALUE"""),5.0) -> 5 | AP17: =IFERROR(__xludf.DUMMYFUNCTION("""COMPUTED_VALUE"""),"ANTONIO'S GRILL Total") -> ANTONIO'S GRILL Total | AR17: =IFERROR(__xludf.DUMMYFUNCTION("""COMPUTED_VALUE"""),5.0) -> 5
A18: SO00000121 | B18: 1250001142.00 | C18: DEPT. OF HUMAN SETTLEMENTS & URBAN DEV'T | D18: 45296 | E18: 44970 | F18: GRACE POLPOL | K18: DEPT. OF HUMAN SETTLEMENTS & URBAN DEV'T | L18: January | M18: 44970 | AL18: =IFERROR(__xludf.DUMMYFUNCTION("""COMPUTED_VALUE"""),"ARM-G INT'L. LOGISTIC INC.") -> ARM-G INT'L. LOGISTIC INC. | AM18: =IFERROR(__xludf.DUMMYFUNCTION("""COMPUTED_VALUE"""),"January") -> January | AN18: =IFERROR(__xludf.DUMMYFUNCTION("""COMPUTED_VALUE"""),1.0) -> 1 | AP18: =IFERROR(__xludf.DUMMYFUNCTION("""COMPUTED_VALUE"""),"ARM-G INT'L. LOGISTIC INC.") -> ARM-G INT'L. LOGISTIC INC. | AQ18: =IFERROR(__xludf.DUMMYFUNCTION("""COMPUTED_VALUE"""),"January") -> January | AR18: =IFERROR(__xludf.DUMMYFUNCTION("""COMPUTED_VALUE"""),1.0) -> 1 | AT18: =IFERROR(__xludf.DUMMYFUNCTION("QUERY('Copy of John 1'!K1:M201, ""SELECT K, COUNT(M) WHERE K IS NOT NULL AND L = 'February' GROUP BY K ORDER BY COUNT(M) DESC LIMIT 5"", 1)"),"CustomerName") -> CustomerName | AU18: =IFERROR(__xludf.DUMMYFUNCTION("""COMPUTED_VALUE"""),"count OrderTotal") -> count OrderTotal
A19: SO00000172 | B19: 1200007688.00 | C19: ANTONIO'S GRILL | D19: 45299 | E19: 525.3 | F19: ANGELI SUMINGIT | K19: ANTONIO'S GRILL | L19: January | M19: 525.3 | AL19: =IFERROR(__xludf.DUMMYFUNCTION("""COMPUTED_VALUE"""),"ARM-G INT'L. LOGISTIC INC. Total") -> ARM-G INT'L. LOGISTIC INC. Total | AN19: =IFERROR(__xludf.DUMMYFUNCTION("""COMPUTED_VALUE"""),1.0) -> 1 | AP19: =IFERROR(__xludf.DUMMYFUNCTION("""COMPUTED_VALUE"""),"ARM-G INT'L. LOGISTIC INC. Total") -> ARM-G INT'L. LOGISTIC INC. Total | AR19: =IFERROR(__xludf.DUMMYFUNCTION("""COMPUTED_VALUE"""),1.0) -> 1 | AT19: =IFERROR(__xludf.DUMMYFUNCTION("""COMPUTED_VALUE"""),"MUNICIPALITY OF LUPON - LGU") -> MUNICIPALITY OF LUPON - LGU | AU19: =IFERROR(__xludf.DUMMYFUNCTION("""COMPUTED_VALUE"""),21.0) -> 21
A20: SO00000196 | B20: 1250000913.00 | C20: FAR EAST ASSOCIATES | D20: 45299 | E20: 2265.45 | F20: ANGELI SUMINGIT | K20: FAR EAST ASSOCIATES | L20: January | M20: 2265.45 | AL20: =IFERROR(__xludf.DUMMYFUNCTION("""COMPUTED_VALUE"""),"ASIAGLOBAL TECHNOLOGIES INC.") -> ASIAGLOBAL TECHNOLOGIES INC. | AM20: =IFERROR(__xludf.DUMMYFUNCTION("""COMPUTED_VALUE"""),"January") -> January | AN20: =IFERROR(__xludf.DUMMYFUNCTION("""COMPUTED_VALUE"""),1.0) -> 1 | AP20: =IFERROR(__xludf.DUMMYFUNCTION("""COMPUTED_VALUE"""),"ASIAGLOBAL TECHNOLOGIES INC.") -> ASIAGLOBAL TECHNOLOGIES INC. | AQ20: =IFERROR(__xludf.DUMMYFUNCTION("""COMPUTED_VALUE"""),"January") -> January | AR20: =IFERROR(__xludf.DUMMYFUNCTION("""COMPUTED_VALUE"""),1.0) -> 1 | AT20: =IFERROR(__xludf.DUMMYFUNCTION("""COMPUTED_VALUE"""),"STENIEL MINDANAO PACKAGING CORPORATION") -> STENIEL MINDANAO PACKAGING CORPORATION | AU20: =IFERROR(__xludf.DUMMYFUNCTION("""COMPUTED_VALUE"""),5.0) -> 5
A21: SO00000168 | B21: 1250010259.00 | C21: LAND BANK - TORIL BRANCH | D21: 45299 | E21: 3256 | F21: GRACE POLPOL | K21: LAND BANK - TORIL BRANCH | L21: January | M21: 3256 | AL21: =IFERROR(__xludf.DUMMYFUNCTION("""COMPUTED_VALUE"""),"ASIAGLOBAL TECHNOLOGIES INC. Total") -> ASIAGLOBAL TECHNOLOGIES INC. Total | AN21: =IFERROR(__xludf.DUMMYFUNCTION("""COMPUTED_VALUE"""),1.0) -> 1 | AP21: =IFERROR(__xludf.DUMMYFUNCTION("""COMPUTED_VALUE"""),"ASIAGLOBAL TECHNOLOGIES INC. Total") -> ASIAGLOBAL TECHNOLOGIES INC. Total | AR21: =IFERROR(__xludf.DUMMYFUNCTION("""COMPUTED_VALUE"""),1.0) -> 1 | AT21: =IFERROR(__xludf.DUMMYFUNCTION("""COMPUTED_VALUE"""),"EC GONZAGA ENTERPRISES") -> EC GONZAGA ENTERPRISES | AU21: =IFERROR(__xludf.DUMMYFUNCTION("""COMPUTED_VALUE"""),4.0) -> 4
A22: SO00000179 | B22: 1250009502.00 | C22: SIMC | D22: 45299 | E22: 4400.6 | F22: ANGELI SUMINGIT | K22: SIMC | L22: January | M22: 4400.6 | AL22: =IFERROR(__xludf.DUMMYFUNCTION("""COMPUTED_VALUE"""),"ASSUMPTION COLLEGE OF DAVAO INC") -> ASSUMPTION COLLEGE OF DAVAO INC | AM22: =IFERROR(__xludf.DUMMYFUNCTION("""COMPUTED_VALUE"""),"February") -> February | AN22: =IFERROR(__xludf.DUMMYFUNCTION("""COMPUTED_VALUE"""),2.0) -> 2 | AP22: =IFERROR(__xludf.DUMMYFUNCTION("""COMPUTED_VALUE"""),"ASSUMPTION COLLEGE OF DAVAO INC") -> ASSUMPTION COLLEGE OF DAVAO INC | AQ22: =IFERROR(__xludf.DUMMYFUNCTION("""COMPUTED_VALUE"""),"February") -> February | AR22: =IFERROR(__xludf.DUMMYFUNCTION("""COMPUTED_VALUE"""),2.0) -> 2 | AT22: =IFERROR(__xludf.DUMMYFUNCTION("""COMPUTED_VALUE"""),"AMALGATED CAPITAL INCORPORATED") -> AMALGATED CAPITAL INCORPORATED | AU22: =IFERROR(__xludf.DUMMYFUNCTION("""COMPUTED_VALUE"""),3.0) -> 3
A23: SO00000219 | B23: 1250010233.00 | C23: HELPMATE INCORPORATED | D23: 45299 | E23: 8254.15 | F23: ANGELI SUMINGIT | K23: HELPMATE INCORPORATED | L23: January | M23: 8254.15 | AL23: =IFERROR(__xludf.DUMMYFUNCTION("""COMPUTED_VALUE"""),"ASSUMPTION COLLEGE OF DAVAO INC Total") -> ASSUMPTION COLLEGE OF DAVAO INC Total | AN23: =IFERROR(__xludf.DUMMYFUNCTION("""COMPUTED_VALUE"""),2.0) -> 2 | AP23: =IFERROR(__xludf.DUMMYFUNCTION("""COMPUTED_VALUE"""),"ASSUMPTION COLLEGE OF DAVAO INC Total") -> ASSUMPTION COLLEGE OF DAVAO INC Total | AR23: =IFERROR(__xludf.DUMMYFUNCTION("""COMPUTED_VALUE"""),2.0) -> 2 | AT23: =IFERROR(__xludf.DUMMYFUNCTION("""COMPUTED_VALUE"""),"ASSUMPTION COLLEGE OF DAVAO INC") -> ASSUMPTION COLLEGE OF DAVAO INC | AU23: =IFERROR(__xludf.DUMMYFUNCTION("""COMPUTED_VALUE"""),2.0) -> 2
A24: SO00000190 | B24: 1250001764.00 | C24: STENIEL MINDANAO PACKAGING CORPORATION | D24: 45299 | E24: 111000 | F24: ANGELI SUMINGIT | K24: STENIEL MINDANAO PACKAGING CORPORATION | L24: January | M24: 111000 | AL24: =IFERROR(__xludf.DUMMYFUNCTION("""COMPUTED_VALUE"""),"ASTROBUILT CONSTRUCTION & DEVELOPMENT") -> ASTROBUILT CONSTRUCTION & DEVELOPMENT | AM24: =IFERROR(__xludf.DUMMYFUNCTION("""COMPUTED_VALUE"""),"January") -> January | AN24: =IFERROR(__xludf.DUMMYFUNCTION("""COMPUTED_VALUE"""),1.0) -> 1 | AP24: =IFERROR(__xludf.DUMMYFUNCTION("""COMPUTED_VALUE"""),"ASTROBUILT CONSTRUCTION & DEVELOPMENT") -> ASTROBUILT CONSTRUCTION & DEVELOPMENT | AQ24: =IFERROR(__xludf.DUMMYFUNCTION("""COMPUTED_VALUE"""),"January") -> January | AR24: =IFERROR(__xludf.DUMMYFUNCTION("""COMPUTED_VALUE"""),1.0) -> 1
A25: SO00000275 | B25: 1250001764.00 | C25: STENIEL MINDANAO PACKAGING CORPORATION | D25: 45300 | E25: 765 | F25: ANGELI SUMINGIT | K25: STENIEL MINDANAO PACKAGING CORPORATION | L25: January | M25: 765 | AL25: =IFERROR(__xludf.DUMMYFUNCTION("""COMPUTED_VALUE"""),"ASTROBUILT CONSTRUCTION & DEVELOPMENT Total") -> ASTROBUILT CONSTRUCTION & DEVELOPMENT Total | AN25: =IFERROR(__xludf.DUMMYFUNCTION("""COMPUTED_VALUE"""),1.0) -> 1 | AP25: =IFERROR(__xludf.DUMMYFUNCTION("""COMPUTED_VALUE"""),"ASTROBUILT CONSTRUCTION & DEVELOPMENT Total") -> ASTROBUILT CONSTRUCTION & DEVELOPMENT Total | AR25: =IFERROR(__xludf.DUMMYFUNCTION("""COMPUTED_VALUE"""),1.0) -> 1
A26: SO00000262 | B26: 1200007688.00 | C26: ANTONIO'S GRILL | D26: 45300 | E26: 1525 | F26: ANGELI SUMINGIT | K26: ANTONIO'S GRILL | L26: January | M26: 1525 | AL26: =IFERROR(__xludf.DUMMYFUNCTION("""COMPUTED_VALUE"""),"AUTOKID SOUTH MINDANAO CORP.") -> AUTOKID SOUTH MINDANAO CORP. | AM26: =IFERROR(__xludf.DUMMYFUNCTION("""COMPUTED_VALUE"""),"February") -> February | AN26: =IFERROR(__xludf.DUMMYFUNCTION("""COMPUTED_VALUE"""),1.0) -> 1 | AP26: =IFERROR(__xludf.DUMMYFUNCTION("""COMPUTED_VALUE"""),"AUTOKID SOUTH MINDANAO CORP.") -> AUTOKID SOUTH MINDANAO CORP. | AQ26: =IFERROR(__xludf.DUMMYFUNCTION("""COMPUTED_VALUE"""),"February") -> February | AR26: =IFERROR(__xludf.DUMMYFUNCTION("""COMPUTED_VALUE"""),1.0) -> 1 | AT26: =AVERAGEIF(AI2:AI1000, "January", AJ2:AJ1000) -> 1.4936709
A27: SO00000263 | B27: 1200007688.00 | C27: ANTONIO'S GRILL | D27: 45300 | E27: 1525 | F27: ANGELI SUMINGIT | K27: ANTONIO'S GRILL | L27: January | M27: 1525 | AL27: =IFERROR(__xludf.DUMMYFUNCTION("""COMPUTED_VALUE"""),"AUTOKID SOUTH MINDANAO CORP. Total") -> AUTOKID SOUTH MINDANAO CORP. Total | AN27: =IFERROR(__xludf.DUMMYFUNCTION("""COMPUTED_VALUE"""),1.0) -> 1 | AP27: =IFERROR(__xludf.DUMMYFUNCTION("""COMPUTED_VALUE"""),"AUTOKID SOUTH MINDANAO CORP. Total") -> AUTOKID SOUTH MINDANAO CORP. Total | AR27: =IFERROR(__xludf.DUMMYFUNCTION("""COMPUTED_VALUE"""),1.0) -> 1 | AT27: =AVERAGEIF(AI2:AI1000, "February", AJ2:AJ1000) -> 1.7608696
A28: SO00000265 | B28: 1200007688.00 | C28: ANTONIO'S GRILL | D28: 45300 | E28: 1525 | F28: ANGELI SUMINGIT | K28: ANTONIO'S GRILL | L28: January | M28: 1525 | AL28: =IFERROR(__xludf.DUMMYFUNCTION("""COMPUTED_VALUE"""),"B.P.I. - HOUSING LOAN") -> B.P.I. - HOUSING LOAN | AM28: =IFERROR(__xludf.DUMMYFUNCTION("""COMPUTED_VALUE"""),"January") -> January | AN28: =IFERROR(__xludf.DUMMYFUNCTION("""COMPUTED_VALUE"""),1.0) -> 1 | AP28: =IFERROR(__xludf.DUMMYFUNCTION("""COMPUTED_VALUE"""),"B.P.I. - HOUSING LOAN") -> B.P.I. - HOUSING LOAN | AQ28: =IFERROR(__xludf.DUMMYFUNCTION("""COMPUTED_VALUE"""),"January") -> January | AR28: =IFERROR(__xludf.DUMMYFUNCTION("""COMPUTED_VALUE"""),1.0) -> 1
A29: SO00000266 | B29: 1200007688.00 | C29: ANTONIO'S GRILL | D29: 45300 | E29: 1525 | F29: ANGELI SUMINGIT | K29: ANTONIO'S GRILL | L29: January | M29: 1525 | AL29: =IFERROR(__xludf.DUMMYFUNCTION("""COMPUTED_VALUE"""),"B.P.I. - HOUSING LOAN Total") -> B.P.I. - HOUSING LOAN Total | AN29: =IFERROR(__xludf.DUMMYFUNCTION("""COMPUTED_VALUE"""),1.0) -> 1 | AP29: =IFERROR(__xludf.DUMMYFUNCTION("""COMPUTED_VALUE"""),"B.P.I. - HOUSING LOAN Total") -> B.P.I. - HOUSING LOAN Total | AR29: =IFERROR(__xludf.DUMMYFUNCTION("""COMPUTED_VALUE"""),1.0) -> 1
A30: SO00000245 | B30: 1250002203.00 | C30: EHB ENTERPRISES & PRINTHAUS | D30: 45300 | E30: 2050 | F30: ANGELI SUMINGIT | K30: EHB ENTERPRISES & PRINTHAUS | L30: January | M30: 2050 | AL30: =IFERROR(__xludf.DUMMYFUNCTION("""COMPUTED_VALUE"""),"B.P.I. - BAJADA (FRONTING CONPINCO)") -> B.P.I. - BAJADA (FRONTING CONPINCO) | AM30: =IFERROR(__xludf.DUMMYFUNCTION("""COMPUTED_VALUE"""),"January") -> January | AN30: =IFERROR(__xludf.DUMMYFUNCTION("""COMPUTED_VALUE"""),1.0) -> 1 | AP30: =IFERROR(__xludf.DUMMYFUNCTION("""COMPUTED_VALUE"""),"B.P.I. - BAJADA (FRONTING CONPINCO)") -> B.P.I. - BAJADA (FRONTING CONPINCO) | AQ30: =IFERROR(__xludf.DUMMYFUNCTION("""COMPUTED_VALUE"""),"January") -> January | AR30: =IFERROR(__xludf.DUMMYFUNCTION("""COMPUTED_VALUE"""),1.0) -> 1
A31: SO00000247 | B31: 1250009745.00 | C31: ML PREMIUM RESOURCES CORP. | D31: 45300 | E31: 3571.75 | F31: ANGELI SUMINGIT | K31: ML PREMIUM RESOURCES CORP. | L31: January | M31: 3571.75 | AL31: =IFERROR(__xludf.DUMMYFUNCTION("""COMPUTED_VALUE"""),"B.P.I. - BAJADA (FRONTING CONPINCO) Total") -> B.P.I. - BAJADA (FRONTING CONPINCO) Total | AN31: =IFERROR(__xludf.DUMMYFUNCTION("""COMPUTED_VALUE"""),1.0) -> 1 | AP31: =IFERROR(__xludf.DUMMYFUNCTION("""COMPUTED_VALUE"""),"B.P.I. - BAJADA (FRONTING CONPINCO) Total") -> B.P.I. - BAJADA (FRONTING CONPINCO) Total | AR31: =IFERROR(__xludf.DUMMYFUNCTION("""COMPUTED_VALUE"""),1.0) -> 1
A32: SO00000296 | B32: 1200008920.00 | C32: ARM-G INT'L. LOGISTIC INC. | D32: 45301 | E32: 5151 | F32: ANGELI SUMINGIT | K32: ARM-G INT'L. LOGISTIC INC. | L32: January | M32: 5151 | AL32: =IFERROR(__xludf.DUMMYFUNCTION("""COMPUTED_VALUE"""),"B.P.I. - LANANG") -> B.P.I. - LANANG | AM32: =IFERROR(__xludf.DUMMYFUNCTION("""COMPUTED_VALUE"""),"January") -> January | AN32: =IFERROR(__xludf.DUMMYFUNCTION("""COMPUTED_VALUE"""),1.0) -> 1 | AP32: =IFERROR(__xludf.DUMMYFUNCTION("""COMPUTED_VALUE"""),"B.P.I. - LANANG") -> B.P.I. - LANANG | AQ32: =IFERROR(__xludf.DUMMYFUNCTION("""COMPUTED_VALUE"""),"January") -> January | AR32: =IFERROR(__xludf.DUMMYFUNCTION("""COMPUTED_VALUE"""),1.0) -> 1
A33: SO00000313 | B33: 1200007890.00 | C33: ASTROBUILT CONSTRUCTION & DEVELOPMENT | D33: 45301 | E33: 7885.3 | F33: ANGELI SUMINGIT | K33: ASTROBUILT CONSTRUCTION & DEVELOPMENT | L33: January | M33: 7885.3 | AL33: =IFERROR(__xludf.DUMMYFUNCTION("""COMPUTED_VALUE"""),"B.P.I. - LANANG Total") -> B.P.I. - LANANG Total | AN33: =IFERROR(__xludf.DUMMYFUNCTION("""COMPUTED_VALUE"""),1.0) -> 1 | AP33: =IFERROR(__xludf.DUMMYFUNCTION("""COMPUTED_VALUE"""),"B.P.I. - LANANG Total") -> B.P.I. - LANANG Total | AR33: =IFERROR(__xludf.DUMMYFUNCTION("""COMPUTED_VALUE"""),1.0) -> 1
A34: SO00000337 | B34: 1250009892.00 | C34: EC GONZAGA ENTERPRISES | D34: 45301 | E34: 10250.5 | F34: ANGELI SUMINGIT | K34: EC GONZAGA ENTERPRISES | L34: January | M34: 10250.5 | AL34: =IFERROR(__xludf.DUMMYFUNCTION("""COMPUTED_VALUE"""),"BANEXCO TRADERS INC.") -> BANEXCO TRADERS INC. | AM34: =IFERROR(__xludf.DUMMYFUNCTION("""COMPUTED_VALUE"""),"January") -> January | AN34: =IFERROR(__xludf.DUMMYFUNCTION("""COMPUTED_VALUE"""),1.0) -> 1 | AP34: =IFERROR(__xludf.DUMMYFUNCTION("""COMPUTED_VALUE"""),"BANEXCO TRADERS INC.") -> BANEXCO TRADERS INC. | AQ34: =IFERROR(__xludf.DUMMYFUNCTION("""COMPUTED_VALUE"""),"January") -> January | AR34: =IFERROR(__xludf.DUMMYFUNCTION("""COMPUTED_VALUE"""),1.0) -> 1
A35: SO00000334 | B35: 1250009892.00 | C35: EC GONZAGA ENTERPRISES | D35: 45301 | E35: 16973.25 | F35: ANGELI SUMINGIT | K35: EC GONZAGA ENTERPRISES | L35: January | M35: 16973.25 | AL35: =IFERROR(__xludf.DUMMYFUNCTION("""COMPUTED_VALUE"""),"BANEXCO TRADERS INC. Total") -> BANEXCO TRADERS INC. Total | AN35: =IFERROR(__xludf.DUMMYFUNCTION("""COMPUTED_VALUE"""),1.0) -> 1 | AP35: =IFERROR(__xludf.DUMMYFUNCTION("""COMPUTED_VALUE"""),"BANEXCO TRADERS INC. Total") -> BANEXCO TRADERS INC. Total | AR35: =IFERROR(__xludf.DUMMYFUNCTION("""COMPUTED_VALUE"""),1.0) -> 1
A36: SO00000357 | B36: 1250010341.00 | C36: EQUINOX SYNERGY OPC | D36: 45302 | E36: 1154 | F36: ANGELI SUMINGIT | K36: EQUINOX SYNERGY OPC | L36: January | M36: 1154 | AL36: =IFERROR(__xludf.DUMMYFUNCTION("""COMPUTED_VALUE"""),"CHARVERSON WOOD INDUSTRY INC.") -> CHARVERSON WOOD INDUSTRY INC. | AM36: =IFERROR(__xludf.DUMMYFUNCTION("""COMPUTED_VALUE"""),"January") -> January | AN36: =IFERROR(__xludf.DUMMYFUNCTION("""COMPUTED_VALUE"""),2.0) -> 2 | AP36: =IFERROR(__xludf.DUMMYFUNCTION("""COMPUTED_VALUE"""),"CHARVERSON WOOD INDUSTRY INC.") -> CHARVERSON WOOD INDUSTRY INC. | AQ36: =IFERROR(__xludf.DUMMYFUNCTION("""COMPUTED_VALUE"""),"January") -> January | AR36: =IFERROR(__xludf.DUMMYFUNCTION("""COMPUTED_VALUE"""),2.0) -> 2
A37: SO00000364 | B37: 1250010341.00 | C37: EQUINOX SYNERGY OPC | D37: 45302 | E37: 3031.5 | F37: ANGELI SUMINGIT | K37: EQUINOX SYNERGY OPC | L37: January | M37: 3031.5 | AL37: =IFERROR(__xludf.DUMMYFUNCTION("""COMPUTED_VALUE"""),"CHARVERSON WOOD INDUSTRY INC. Total") -> CHARVERSON WOOD INDUSTRY INC. Total | AN37: =IFERROR(__xludf.DUMMYFUNCTION("""COMPUTED_VALUE"""),2.0) -> 2 | AP37: =IFERROR(__xludf.DUMMYFUNCTION("""COMPUTED_VALUE"""),"CHARVERSON WOOD INDUSTRY INC. Total") -> CHARVERSON WOOD INDUSTRY INC. Total | AR37: =IFERROR(__xludf.DUMMYFUNCTION("""COMPUTED_VALUE"""),2.0) -> 2
A38: SO00000342 | B38: 1250001348.00 | C38: BANEXCO TRADERS INC. | D38: 45302 | E38: 4490.4 | F38: ANGELI SUMINGIT | K38: BANEXCO TRADERS INC. | L38: January | M38: 4490.4 | AL38: =IFERROR(__xludf.DUMMYFUNCTION("""COMPUTED_VALUE"""),"CHEVRON PHILIPPINES INC. (FORMER CALTEX)") -> CHEVRON PHILIPPINES INC. (FORMER CALTEX) | AM38: =IFERROR(__xludf.DUMMYFUNCTION("""COMPUTED_VALUE"""),"February") -> February | AN38: =IFERROR(__xludf.DUMMYFUNCTION("""COMPUTED_VALUE"""),1.0) -> 1 | AP38: =IFERROR(__xludf.DUMMYFUNCTION("""COMPUTED_VALUE"""),"CHEVRON PHILIPPINES INC. (FORMER CALTEX)") -> CHEVRON PHILIPPINES INC. (FORMER CALTEX) | AQ38: =IFERROR(__xludf.DUMMYFUNCTION("""COMPUTED_VALUE"""),"February") -> February | AR38: =IFERROR(__xludf.DUMMYFUNCTION("""COMPUTED_VALUE"""),1.0) -> 1
A39: SO00000346 | B39: 1250000034.00 | C39: LAND BANK OF THE PHILS. - RAMON MAGSAYSAY | D39: 45302 | E39: 10550 | F39: GRACE POLPOL | K39: LAND BANK OF THE PHILS. - RAMON MAGSAYSAY | L39: January | M39: 10550 | AL39: =IFERROR(__xludf.DUMMYFUNCTION("""COMPUTED_VALUE"""),"CHEVRON PHILIPPINES INC. (FORMER CALTEX) Total") -> CHEVRON PHILIPPINES INC. (FORMER CALTEX) Total | AN39: =IFERROR(__xludf.DUMMYFUNCTION("""COMPUTED_VALUE"""),1.0) -> 1 | AP39: =IFERROR(__xludf.DUMMYFUNCTION("""COMPUTED_VALUE"""),"CHEVRON PHILIPPINES INC. (FORMER CALTEX) Total") -> CHEVRON PHILIPPINES INC. (FORMER CALTEX) Total | AR39: =IFERROR(__xludf.DUMMYFUNCTION("""COMPUTED_VALUE"""),1.0) -> 1
A40: SO00000402 | B40: 1250009745.00 | C40: ML PREMIUM RESOURCES CORP. | D40: 45303 | E40: 744 | F40: ANGELI SUMINGIT | K40: ML PREMIUM RESOURCES CORP. | L40: January | M40: 744 | AL40: =IFERROR(__xludf.DUMMYFUNCTION("""COMPUTED_VALUE"""),"CITY GOVERNMENT OF DAVAO") -> CITY GOVERNMENT OF DAVAO | AM40: =IFERROR(__xludf.DUMMYFUNCTION("""COMPUTED_VALUE"""),"November") -> November | AN40: =IFERROR(__xludf.DUMMYFUNCTION("""COMPUTED_VALUE"""),1.0) -> 1 | AP40: =IFERROR(__xludf.DUMMYFUNCTION("""COMPUTED_VALUE"""),"CITY GOVERNMENT OF DAVAO") -> CITY GOVERNMENT OF DAVAO | AQ40: =IFERROR(__xludf.DUMMYFUNCTION("""COMPUTED_VALUE"""),"November") -> November | AR40: =IFERROR(__xludf.DUMMYFUNCTION("""COMPUTED_VALUE"""),1.0) -> 1
...

Sheet John 2
A1: OrderNbr | B1: Customer | C1: CustomerName | D1: Date | E1: OrderTotal | F1: CreatedBy
A2: SO00000687 | B2: 1250000116 | C2: CITY GOVERNMENT OF DAVAO | D2: 45250 | E2: ₱4372.25 | F2: GRACE POLPOL
A3: SO00000012 | B3: 1250000505 | C3: STAR PAPER CORPORATION | D3: 45294 | E3: ₱1362.00 | F3: ANGELI SUMINGIT
A4: SO00000005 | B4: 1250001764 | C4: STENIEL MINDANAO PACKAGING CORPORATION | D4: 45294 | E4: ₱1500.00 | F4: ANGELI SUMINGIT
A5: SO00000028 | B5: 1250001496 | C5: COMFAC CORPORATION | D5: 45294 | E5: ₱1916.00 | F5: ANGELI SUMINGIT
A6: SO00000021 | B6: 1200006565 | C6: NXTGEN TECHNOLOGIES INC | D6: 45294 | E6: ₱2148.80 | F6: ANGELI SUMINGIT
A7: SO00000026 | B7: 1250004966 | C7: INFIMAX HEALTH PRODUCTS | D7: 45294 | E7: ₱2365.80 | F7: ANGELI SUMINGIT
A8: SO00000020 | B8: 1250001764 | C8: STENIEL MINDANAO PACKAGING CORPORATION | D8: 45294 | E8: ₱2367.50 | F8: ANGELI SUMINGIT
A9: SO00000013 | B9: 1250001142 | C9: DEPT. OF HUMAN SETTLEMENTS & URBAN DEV'T | D9: 45294 | E9: ₱38256.00 | F9: GRACE POLPOL
A10: SO00000097 | B10: 1200006417 | C10: PHIL.FIBER INDUSTRY DEV'T AUTHORITY | D10: 45295 | E10: ₱1500.00 | F10: GRACE POLPOL
A11: SO00000071 | B11: 1250010315 | C11: HI5 SOLUTIONS OPC | D11: 45295 | E11: ₱1600.00 | F11: ANGELI SUMINGIT
A12: SO00000096 | B12: 1250004938 | C12: B.P.I. - BAJADA (FRONTING CONPINCO) | D12: 45295 | E12: ₱4762.10 | F12: ANGELI SUMINGIT
A13: SO00000070 | B13: 1250003997 | C13: INSULAR OIL CORPORATION | D13: 45295 | E13: ₱5265.00 | F13: ANGELI SUMINGIT
... A201: SO00001324 | B201: 1250001273 | C201: MILLENNIUM SPECIALTY COCO PRODUCTSINC. | D201: 45337 | E201: ₱1200.00 | F201: ANGELI SUMINGIT

Sheet Johnreyexel

Sheet johnreyexcl
A1: OrderNbr | B1: Customer | C1: CustomerName | D1: Date | E1: OrderTotal | F1: CreatedBy
A2: SO00000687 | B2: 1250000116 | C2: CITY GOVERNMENT OF DAVAO | D2: 45250 | E2: ₱4372.25 | F2: GRACE POLPOL
A3: SO00000012 | B3: 1250000505 | C3: STAR PAPER CORPORATION | D3: 45294 | E3: ₱1362.00 | F3: ANGELI SUMINGIT
A4: SO00000005 | B4: 1250001764 | C4: STENIEL MINDANAO PACKAGING CORPORATION | D4: 45294 | E4: ₱1500.00 | F4: ANGELI SUMINGIT
A5: SO00000028 | B5: 1250001496 | C5: COMFAC CORPORATION | D5: 45294 | E5: ₱1916.00 | F5: ANGELI SUMINGIT
A6: SO00000021 | B6: 1200006565 | C6: NXTGEN TECHNOLOGIES INC | D6: 45294 | E6: ₱2148.80 | F6: ANGELI SUMINGIT
A7: SO00000026 | B7: 1250004966 | C7: INFIMAX HEALTH PRODUCTS | D7: 45294 | E7: ₱2365.80 | F7: ANGELI SUMINGIT
A8: SO00000020 | B8: 1250001764 | C8: STENIEL MINDANAO PACKAGING CORPORATION | D8: 45294 | E8: ₱2367.50 | F8: ANGELI SUMINGIT
A9: SO00000013 | B9: 1250001142 | C9: DEPT. OF HUMAN SETTLEMENTS & URBAN DEV'T | D9: 45294 | E9: ₱38256.00 | F9: GRACE POLPOL
A10: SO00000097 | B10: 1200006417 | C10: PHIL.FIBER INDUSTRY DEV'T AUTHORITY | D10: 45295 | E10: ₱1500.00 | F10: GRACE POLPOL
A11: SO00000071 | B11: 1250010315 | C11: HI5 SOLUTIONS OPC | D11: 45295 | E11: ₱1600.00 | F11: ANGELI SUMINGIT
A12: SO00000096 | B12: 1250004938 | C12: B.P.I. - BAJADA (FRONTING CONPINCO) | D12: 45295 | E12: ₱4762.10 | F12: ANGELI SUMINGIT
A13: SO00000070 | B13: 1250003997 | C13: INSULAR OIL CORPORATION | D13: 45295 | E13: ₱5265.00 | F13: ANGELI SUMINGIT
... A201: SO00001324 | B201: 1250001273 | C201: MILLENNIUM SPECIALTY COCO PRODUCTSINC. | D201: 45337 | E201: ₱1200.00 | F201: ANGELI SUMINGIT

Sheet Pivot Table 2
